<?xml version="1.0" encoding="utf-8"?>
<!-- This URDF was automatically created by SolidWorks to URDF Exporter! Originally created by Stephen Brawner (brawner@gmail.com) 
     Commit Version: 1.6.0-1-g15f4949  Build Version: 1.6.7594.29634
     For more information, please see http://wiki.ros.org/sw_urdf_exporter -->
<robot
  name="rover_21_description_zed" xmlns:xacro="http://www.ros.org/wiki/xacro">

  <!--xacro:include filename="$(find rover_21_description_zed)/urdf/vlp16.urdf.xacro"/>
  <xacro:property name="cameraSize" value="0.05"/>
  <xacro:property name="cameraMass" value="0.1"/-->
  <xacro:include filename="$(find rover_21_description_zed)/urdf/zed2.xacro"/>

  <link
    name="base_link">
    <inertial>
      <origin
        xyz="-0.0597176388871317 -2.21514952908342E-09 0.0432014783103323"
        rpy="0 0 0" />
      <mass
        value="7.6451763291456" />
      <inertia
        ixx="0.168439329083486"
        ixy="-1.08629887891622E-05"
        ixz="0.0407415251600241"
        iyy="0.481545696094267"
        iyz="5.75369711790317E-08"
        izz="0.541121238422161" />
    </inertial>
    <visual>
      <origin
        xyz="0 0 0"
        rpy="0 0 0" />
      <geometry>
        <mesh
          filename="package://rover_21_description_zed/meshes/base_link.STL" />
      </geometry>
      <material
        name="">
        <color
          rgba="0.792156862745098 0.819607843137255 0.933333333333333 1" />
      </material>
    </visual>
    <collision>
      <origin
        xyz="0 0 0"
        rpy="0 0 0" />
      <geometry>
        <mesh
          filename="package://rover_21_description_zed/meshes/base_link.STL" />
      </geometry>
    </collision>
  </link>
  <link
    name="left_front_link">
    <inertial>
      <origin
        xyz="-0.0755097276903981 0.000138247434987249 -4.79303458726932E-05"
        rpy="0 0 0" />
      <mass
        value="1.15731252096219" />
      <inertia
        ixx="0.0178302511822237"
        ixy="-2.09274363582099E-06"
        ixz="1.4204407926078E-06"
        iyy="0.00968270185063617"
        iyz="1.80036299754407E-06"
        izz="0.00969344166305502" />
    </inertial>
    <visual>
      <origin
        xyz="0 0 0"
        rpy="0 0 0" />
      <geometry>
        <mesh
          filename="package://rover_21_description_zed/meshes/left_front_link.STL" />
      </geometry>
      <material
        name="">
        <color
          rgba="0.792156862745098 0.819607843137255 0.933333333333333 1" />
      </material>
    </visual>
    <collision>
      <origin
        xyz="0 0 0"
        rpy="0 0 0" />
      <geometry>
        <mesh
          filename="package://rover_21_description_zed/meshes/left_front_link.STL" />
      </geometry>
    </collision>
  </link>
  <joint
    name="left_front_joint"
    type="continuous">
    <origin
      xyz="0.353294657130572 0.3625 -0.154224967578181"
      rpy="-2.0786047357804 0 -1.5707963267949" />
    <parent
      link="base_link" />
    <child
      link="left_front_link" />
    <axis
      xyz="-1 0 0" />
  </joint>
  <link
    name="right_front_link">
    <inertial>
      <origin
        xyz="-2.84518155616587E-05 0.00014352757758429 -0.0754466264782706"
        rpy="0 0 0" />
      <mass
        value="1.15731252096219" />
      <inertia
        ixx="0.00969372906416445"
        ixy="2.68465121779082E-07"
        ixz="-1.11897159373537E-06"
        iyy="0.00968241444952688"
        iyz="2.26828802029305E-06"
        izz="0.0178302511822238" />
    </inertial>
    <visual>
      <origin
        xyz="0 0 0"
        rpy="0 0 0" />
      <geometry>
        <mesh
          filename="package://rover_21_description_zed/meshes/right_front_link.STL" />
      </geometry>
      <material
        name="">
        <color
          rgba="0.792156862745098 0.819607843137255 0.933333333333333 1" />
      </material>
    </visual>
    <collision>
      <origin
        xyz="0 0 0"
        rpy="0 0 0" />
      <geometry>
        <mesh
          filename="package://rover_21_description_zed/meshes/right_front_link.STL" />
      </geometry>
    </collision>
  </link>
  <joint
    name="right_front_joint"
    type="continuous">
    <origin
      xyz="0.353351994708173 -0.3625 -0.154125745497893"
      rpy="-1.5707963267949 0.966931818667219 0" />
    <parent
      link="base_link" />
    <child
      link="right_front_link" />
    <axis
      xyz="0 0 1" />
  </joint>
  <link
    name="left_rear_link">
    <inertial>
      <origin
        xyz="-2.8451815541175E-05 0.000143527577594393 0.0755097276903982"
        rpy="0 0 0" />
      <mass
        value="1.15731252096219" />
      <inertia
        ixx="0.00969372906416443"
        ixy="2.6846512179334E-07"
        ixz="-1.11897159373079E-06"
        iyy="0.00968241444952685"
        iyz="2.26828802029616E-06"
        izz="0.0178302511822237" />
    </inertial>
    <visual>
      <origin
        xyz="0 0 0"
        rpy="0 0 0" />
      <geometry>
        <mesh
          filename="package://rover_21_description_zed/meshes/left_rear_link.STL" />
      </geometry>
      <material
        name="">
        <color
          rgba="0.792156862745098 0.819607843137255 0.933333333333333 1" />
      </material>
    </visual>
    <collision>
      <origin
        xyz="0 0 0"
        rpy="0 0 0" />
      <geometry>
        <mesh
          filename="package://rover_21_description_zed/meshes/left_rear_link.STL" />
      </geometry>
    </collision>
  </link>
  <joint
    name="left_rear_joint"
    type="continuous">
    <origin
      xyz="-0.355493804489844 0.3625 -0.150372421028072"
      rpy="1.5707963267949 1.53320191104535 3.14159265358979" />
    <parent
      link="base_link" />
    <child
      link="left_rear_link" />
    <axis
      xyz="0 0 1" />
  </joint>
  <link
    name="right_rear_link">
    <inertial>
      <origin
        xyz="-2.84515837579713E-05 0.000143527620351219 -0.0754466264782706"
        rpy="0 0 0" />
      <mass
        value="1.15731252096219" />
      <inertia
        ixx="0.00969372911382251"
        ixy="2.68439980844609E-07"
        ixz="-1.11897159373792E-06"
        iyy="0.00968241439986873"
        iyz="2.26828802029381E-06"
        izz="0.0178302511822237" />
    </inertial>
    <visual>
      <origin
        xyz="0 0 0"
        rpy="0 0 0" />
      <geometry>
        <mesh
          filename="package://rover_21_description_zed/meshes/right_rear_link.STL" />
      </geometry>
      <material
        name="">
        <color
          rgba="0.792156862745098 0.819607843137255 0.933333333333333 1" />
      </material>
    </visual>
    <collision>
      <origin
        xyz="0 0 0"
        rpy="0 0 0" />
      <geometry>
        <mesh
          filename="package://rover_21_description_zed/meshes/right_rear_link.STL" />
      </geometry>
    </collision>
  </link>
  <joint
    name="right_rear_joint"
    type="continuous">
    <origin
      xyz="-0.353922288632598 -0.3625 -0.150480055091568"
      rpy="-1.5707963267949 0.867399709619945 0" />
    <parent
      link="base_link" />
    <child
      link="right_rear_link" />
    <axis
      xyz="0 0 1" />
  </joint>
 
  <!--vlp16 prefix="base" topic="/velodyne_points" hz="10" samples="440" gpu="true" max_range="5.0" min_range="0.1" min_angle="-2.39982772" max_angle="2.39982772"/>

  <joint name="base_laser_joint" type="fixed">
    <origin xyz="0.25 0.0 0.12" rpy="0 0 0" />
    <parent link="base_link"/>
    <child link="velodyne"/>
  </joint>

  <link name="camera">
    <collision>
      <origin xyz="0 0 0" rpy="0 0 0"/>
      <geometry>
        <box size="${cameraSize} ${cameraSize} ${cameraSize}"/>
      </geometry>
    </collision>

    <visual>
      <origin xyz="0 0 0" rpy="0 0 0"/>
      <geometry>
        <box size="${cameraSize} ${cameraSize} ${cameraSize}"/>
      </geometry>
      <material name="green"/>
    </visual>

    <inertial>
      <mass value="${cameraMass}" />
      <origin xyz="0 0 0" rpy="0 0 0"/>
      <box_inertia m="${cameraMass}" x="${cameraSize}" y="${cameraSize}" z="${cameraSize}" />
      <inertia ixx="1e-6" ixy="0" ixz="0" iyy="1e-6" iyz="0" izz="1e-6" />
    </inertial>
  </link>

  <joint name="camera_joint" type="fixed">
    <axis xyz="1 1 0" />
    <origin xyz="0.25 0.0 0.20" rpy="0 0 0"/>
    <parent link="base_link"/>
    <child link="camera"/>
  </joint-->

  
  <joint name="zed2_tilt_head_joint" type="fixed">
    <origin xyz="0.3 0 0.09" rpy="0 0.0 0"/> <!-- 23.83 degree tilt -->
    <parent link="base_link"/>
    <child link="zed2_tilt_head_link"/>
  </joint>

  <link name="zed2_tilt_head_link">
    <inertial>
      <mass value="0.108614"/>
      <origin xyz="0 -0.008564 0.015313"/>
      <inertia
        ixx="7.371e-5" ixy="0.0" ixz="1.326071e-6"
        iyy="3.14e-5" iyz="-1.424e-5"
        izz="6.13e-5"/>
    </inertial>
    <visual>
      <origin xyz="0 0 0" rpy="0 0 ${pi}"/>
      <geometry>
        <mesh filename="package://rover_21_description_zed/meshes/Manfrotto_head.dae"/>
      </geometry>
    </visual>
    <collision>
      <origin xyz="0 0 0" rpy="0 0 ${pi}"/>
      <geometry>
        <mesh filename="package://rover_21_description_zed/meshes/Manfrotto_head.dae"/>
      </geometry>
    </collision>
  </link>

  <joint name="zed2_camera_center_joint" type="fixed">
    <parent link="zed2_tilt_head_link"/>
    <child link="zed2_camera_center"/>
    <origin xyz="0 0 0.0486" rpy="0 0.0 0"/>
  </joint>

  <zed2 link_prefix="zed2_tilt_head_link" 
              joint_prefix="zed2_camera_center_joint"/>

  <xacro:zed2_gazebo robot_ns="robot_description"/>
  
  <transmission name="left_front_trans" type="SimpleTransmission">
    <type>transmission_interface/SimpleTransmission</type>
    <actuator name="left_front_motor">
      <mechanicalReduction>1</mechanicalReduction>
    </actuator>
    <joint name="left_front_joint">
      <hardwareInterface>hardware_interface/VelocityJointInterface</hardwareInterface>
    </joint>
  </transmission>

  <transmission name="right_front_trans" type="SimpleTransmission">
    <type>transmission_interface/SimpleTransmission</type>
    <actuator name="right_front_motor">
      <mechanicalReduction>1</mechanicalReduction>
    </actuator>
    <joint name="right_front_joint">
      <hardwareInterface>hardware_interface/VelocityJointInterface</hardwareInterface>
    </joint>
  </transmission>

  <transmission name="left_rear_trans" type="SimpleTransmission">
    <type>transmission_interface/SimpleTransmission</type>
    <actuator name="left_rear_motor">
      <mechanicalReduction>1</mechanicalReduction>
    </actuator>
    <joint name="left_rear_joint">
      <hardwareInterface>hardware_interface/VelocityJointInterface</hardwareInterface>
    </joint>
  </transmission>

  <transmission name="right_rear_trans" type="SimpleTransmission">
    <type>transmission_interface/SimpleTransmission</type>
    <actuator name="right_rear_motor">
      <mechanicalReduction>1</mechanicalReduction>
    </actuator>
    <joint name="right_rear_joint">
      <hardwareInterface>hardware_interface/VelocityJointInterface</hardwareInterface>
    </joint>
  </transmission>

  <gazebo>
    <plugin name="gazebo_ros_control" filename="libgazebo_ros_control.so">
      <robotSimType>gazebo_ros_control/DefaultRobotHWSim</robotSimType>
      <legacyModeNS>true</legacyModeNS>
    </plugin>
  </gazebo>

   <gazebo>
    <plugin name="imu_controller" filename="libhector_gazebo_ros_imu.so">
      <updateRate>30.0</updateRate>
      <bodyName>base_link</bodyName>
      <topicName>/imu/data</topicName>
      <accelDrift>0.005 0.005 0.005</accelDrift>
      <accelGaussianNoise>0.005 0.005 0.005</accelGaussianNoise>
      <rateDrift>0.005 0.005 0.005 </rateDrift>
      <rateGaussianNoise>0.005 0.005 0.005 </rateGaussianNoise>
      <headingDrift>0.005</headingDrift>[ERROR] [1555346159.311804930, 0.098000000]: 
      <headingGaussianNoise>0.005</headingGaussianNoise>
    </plugin>
  </gazebo>

  <gazebo>
    <plugin name="gps_controller" filename="libhector_gazebo_ros_gps.so">
      <updateRate>30</updateRate>
      <bodyName>base_link</bodyName>
      <frameId>base_link</frameId>
      <topicName>gps/fix</topicName>
      <velocityTopicName>navsat/vel</velocityTopicName>
      <referenceLatitude>41.1052670854</referenceLatitude>
      <referenceLongitude>29.023378124</referenceLongitude>
      <referenceHeading>0</referenceHeading>
      <referenceAltitude>0</referenceAltitude>
      <drift>0.0001 0.0001 0.0001</drift>
    </plugin>
  </gazebo>

  <gazebo reference="camera">
     <sensor type="camera" name="camera">
       <update_rate>30.0</update_rate>
       <camera name="camera">
         <horizontal_fov>1.3962634</horizontal_fov>
         <image>
           <width>800</width>
           <height>800</height>
           <format>R8G8B8</format>
         </image>
         <clip>
           <near>0.02</near>
           <far>300</far>
         </clip>
         <noise>
           <type>gaussian</type>
           <mean>0.0</mean>
           <stddev>0.007</stddev>
         </noise>
       </camera>
       <plugin name="camera_controller" filename="libgazebo_ros_camera.so">
         <alwaysOn>true</alwaysOn>
         <updateRate>0.0</updateRate>
         <cameraName>/rover_20/camera</cameraName>
         <imageTopicName>camera_view</imageTopicName>
         <cameraInfoTopicName>camera_info</cameraInfoTopicName>
         <frameName>camera</frameName>
         <hackBaseline>0.07</hackBaseline>
         <distortionK1>0.0</distortionK1>
         <distortionK2>0.0</distortionK2>
         <distortionK3>0.0</distortionK3>
         <distortionT1>0.0</distortionT1>
         <distortionT2>0.0</distortionT2>
       </plugin>
     </sensor>
   </gazebo>
</robot>
