<?xml version="1.0"?>
<robot name="rover_22" xmlns:xacro="http://www.ros.org/wiki/xacro">

  <!-- Import zed2 urdf-->
  <xacro:include filename="$(find rover_22_description_zed)/urdf/zed2.xacro"/>
  <xacro:include filename="$(find rover_22_description_zed)/urdf/materials.xacro" />
  <xacro:include filename="$(find rover_22_description_zed)/urdf/rover_22.trans" />
  <xacro:include filename="$(find rover_22_description_zed)/urdf/rover_22.gazebo" />
  <link name="base_link">
    <inertial>
      <origin rpy="0 0 0" xyz="0.3900216643223882 -0.05651805156877747 -0.032478855168978776" />
      <mass value="9.132305216420624" />
      <inertia ixx="0.669816" ixy="1.6e-05" ixz="8e-06" iyy="1.077053" iyz="-0.006568" izz="1.72329" />
    </inertial>
    <visual>
      <origin rpy="0 0 0" xyz="0 0 0" />
      <geometry>
        <mesh filename="package://rover_22_description_zed/meshes/base_link.stl" scale="0.001 0.001 0.001" />
      </geometry>
      <material name="silver" />
    </visual>
    <collision>
      <origin rpy="0 0 0" xyz="0 0 0" />
      <geometry>
        <mesh filename="package://rover_22_description_zed/meshes/base_link.stl" scale="0.001 0.001 0.001" />
      </geometry>
    </collision>
  </link>

  <link name="steering_leftfront_link_1">
    <inertial>
      <origin rpy="0 0 0" xyz="0.05462767340500796 -4.160167264566361e-07 -0.11312448251790846" />
      <mass value="1.4162605923803364" />
      <inertia ixx="0.006106" ixy="-0.0" ixz="-0.000193" iyy="0.007213" iyz="-0.0" izz="0.002603" />
    </inertial>
    <visual>
      <origin rpy="0 0 0" xyz="0.071 -0.460515 0.071298" />
      <geometry>
        <mesh filename="package://rover_22_description_zed/meshes/steering_leftfront_link_1.stl" scale="0.001 0.001 0.001" />
      </geometry>
      <material name="silver" />
    </visual>
    <collision>
      <origin rpy="0 0 0" xyz="0.071 -0.460515 0.071298" />
      <geometry>
        <mesh filename="package://rover_22_description_zed/meshes/steering_leftfront_link_1.stl" scale="0.001 0.001 0.001" />
      </geometry>
    </collision>
  </link>

  <link name="steering_leftrear_link_1">
    <inertial>
      <origin rpy="0 0 0" xyz="0.05462767340500775 4.160167182964969e-07 -0.11312448251790536" />
      <mass value="1.4162605923803364" />
      <inertia ixx="0.006106" ixy="-0.0" ixz="-0.000193" iyy="0.007213" iyz="-0.0" izz="0.002603" />
    </inertial>
    <visual>
      <origin rpy="0 0 0" xyz="0.071 0.460515 0.071298" />
      <geometry>
        <mesh filename="package://rover_22_description_zed/meshes/steering_leftrear_link_1.stl" scale="0.001 0.001 0.001" />
      </geometry>
      <material name="silver" />
    </visual>
    <collision>
      <origin rpy="0 0 0" xyz="0.071 0.460515 0.071298" />
      <geometry>
        <mesh filename="package://rover_22_description_zed/meshes/steering_leftrear_link_1.stl" scale="0.001 0.001 0.001" />
      </geometry>
    </collision>
  </link>

  <link name="steering_rightrear_link_1">
    <inertial>
      <origin rpy="0 0 0" xyz="-0.054627673405008514 4.160167272893034e-07 -0.11312448251790566" />
      <mass value="1.4162605923803364" />
      <inertia ixx="0.006106" ixy="-0.0" ixz="0.000193" iyy="0.007213" iyz="0.0" izz="0.002603" />
    </inertial>
    <visual>
      <origin rpy="0 0 0" xyz="-0.851 0.460515 0.071298" />
      <geometry>
        <mesh filename="package://rover_22_description_zed/meshes/steering_rightrear_link_1.stl" scale="0.001 0.001 0.001" />
      </geometry>
      <material name="silver" />
    </visual>
    <collision>
      <origin rpy="0 0 0" xyz="-0.851 0.460515 0.071298" />
      <geometry>
        <mesh filename="package://rover_22_description_zed/meshes/steering_rightrear_link_1.stl" scale="0.001 0.001 0.001" />
      </geometry>
    </collision>
  </link>

  <link name="steering_rightfront_link_1">
    <inertial>
      <origin rpy="0 0 0" xyz="-0.054627673405008514 -4.1601671740831847e-07 -0.1131244825179086" />
      <mass value="1.4162605923803364" />
      <inertia ixx="0.006106" ixy="-0.0" ixz="0.000193" iyy="0.007213" iyz="0.0" izz="0.002603" />
    </inertial>
    <visual>
      <origin rpy="0 0 0" xyz="-0.851 -0.460515 0.071298" />
      <geometry>
        <mesh filename="package://rover_22_description_zed/meshes/steering_rightfront_link_1.stl" scale="0.001 0.001 0.001" />
      </geometry>
      <material name="silver" />
    </visual>
    <collision>
      <origin rpy="0 0 0" xyz="-0.851 -0.460515 0.071298" />
      <geometry>
        <mesh filename="package://rover_22_description_zed/meshes/steering_rightfront_link_1.stl" scale="0.001 0.001 0.001" />
      </geometry>
    </collision>
  </link>

  <link name="wheel_leftfront_link_1">
    <inertial>
      <origin rpy="0 0 0" xyz="0.012081210278825166 -7.964965005857749e-05 -7.809793840796164e-07" />
      <mass value="15.748238406301127" />
      <inertia ixx="0.202408" ixy="-1e-05" ixz="0.0" iyy="0.110179" iyz="-1e-06" izz="0.110074" />
    </inertial>
    <visual>
      <origin rpy="0 0 0" xyz="0.086 -0.460515 0.223298" />
      <geometry>
        <mesh filename="package://rover_22_description_zed/meshes/wheel_leftfront_link_1.stl" scale="0.001 0.001 0.001" />
      </geometry>
      <material name="silver" />
    </visual>
    <collision>
      <origin rpy="0 0 0" xyz="0.086 -0.460515 0.223298" />
      <geometry>
        <mesh filename="package://rover_22_description_zed/meshes/wheel_leftfront_link_1.stl" scale="0.001 0.001 0.001" />
      </geometry>
    </collision>
  </link>

  <link name="wheel_leftrear_link_1">
    <inertial>
      <origin rpy="0 0 0" xyz="0.012081210278825125 -7.881761661360231e-05 -7.809793807211918e-07" />
      <mass value="15.748238406301127" />
      <inertia ixx="0.202408" ixy="-1e-05" ixz="0.0" iyy="0.110179" iyz="-1e-06" izz="0.110074" />
    </inertial>
    <visual>
      <origin rpy="0 0 0" xyz="0.086 0.460515 0.223298" />
      <geometry>
        <mesh filename="package://rover_22_description_zed/meshes/wheel_leftrear_link_1.stl" scale="0.001 0.001 0.001" />
      </geometry>
      <material name="silver" />
    </visual>
    <collision>
      <origin rpy="0 0 0" xyz="0.086 0.460515 0.223298" />
      <geometry>
        <mesh filename="package://rover_22_description_zed/meshes/wheel_leftrear_link_1.stl" scale="0.001 0.001 0.001" />
      </geometry>
    </collision>
  </link>

  <link name="wheel_rightrear_link_1">
    <inertial>
      <origin rpy="0 0 0" xyz="-0.01208121027882636 -7.88176166130472e-05 1.5670461361305676e-06" />
      <mass value="15.748238406301127" />
      <inertia ixx="0.202408" ixy="1e-05" ixz="0.0" iyy="0.110179" iyz="1e-06" izz="0.110074" />
    </inertial>
    <visual>
      <origin rpy="0 0 0" xyz="-0.866 0.460515 0.223298" />
      <geometry>
        <mesh filename="package://rover_22_description_zed/meshes/wheel_rightrear_link_1.stl" scale="0.001 0.001 0.001" />
      </geometry>
      <material name="silver" />
    </visual>
    <collision>
      <origin rpy="0 0 0" xyz="-0.866 0.460515 0.223298" />
      <geometry>
        <mesh filename="package://rover_22_description_zed/meshes/wheel_rightrear_link_1.stl" scale="0.001 0.001 0.001" />
      </geometry>
    </collision>
  </link>

  <link name="wheel_rightfront_link_1">
    <inertial>
      <origin rpy="0 0 0" xyz="-0.012081210278826138 -7.964965005852198e-05 1.5670461332162322e-06" />
      <mass value="15.748238406301127" />
      <inertia ixx="0.202408" ixy="1e-05" ixz="0.0" iyy="0.110179" iyz="1e-06" izz="0.110074" />
    </inertial>
    <visual>
      <origin rpy="0 0 0" xyz="-0.866 -0.460515 0.223298" />
      <geometry>
        <mesh filename="package://rover_22_description_zed/meshes/wheel_rightfront_link_1.stl" scale="0.001 0.001 0.001" />
      </geometry>
      <material name="silver" />
    </visual>
    <collision>
      <origin rpy="0 0 0" xyz="-0.866 -0.460515 0.223298" />
      <geometry>
        <mesh filename="package://rover_22_description_zed/meshes/wheel_rightfront_link_1.stl" scale="0.001 0.001 0.001" />
      </geometry>
    </collision>
  </link>

  <joint name="steering_leftfront_joint" type="revolute">
    <origin rpy="0 0 0" xyz="-0.071 0.460515 -0.071298" />
    <parent link="base_link" />
    <child link="steering_leftfront_link_1" />
    <axis xyz="-0.0 -0.0 1.0" />
    <limit lower="-3.49" upper="3.49" effort="200" velocity="20" />
  </joint>

  <joint name="steering_leftrear_joint" type="revolute">
    <origin rpy="0 0 0" xyz="-0.071 -0.460515 -0.071298" />
    <parent link="base_link" />
    <child link="steering_leftrear_link_1" />
    <axis xyz="0.0 0.0 1.0" />
    <limit lower="-3.49" upper="3.49" effort="200" velocity="20" />
  </joint>

  <joint name="steering_rightrear_joint" type="revolute">
    <origin rpy="0 0 0" xyz="0.851 -0.460515 -0.071298" />
    <parent link="base_link" />
    <child link="steering_rightrear_link_1" />
    <axis xyz="0.0 0.0 1.0" />
    <limit lower="-3.49" upper="3.49" effort="200" velocity="20" />
  </joint>

  <joint name="steering_rightfront_joint" type="revolute">
    <origin rpy="0 0 0" xyz="0.851 0.460515 -0.071298" />
    <parent link="base_link" />
    <child link="steering_rightfront_link_1" />
    <axis xyz="-0.0 -0.0 1.0" />
    <limit lower="-3.49" upper="3.49" effort="200" velocity="20" />
  </joint>

  <joint name="wheel_leftfront_joint" type="continuous">
    <origin rpy="0 0 0" xyz="-0.015 0.0 -0.152" />
    <parent link="steering_leftfront_link_1" />
    <child link="wheel_leftfront_link_1" />
    <axis xyz="-1.0 -0.0 -0.0" />
  </joint>

  <joint name="wheel_leftrear_joint" type="continuous">
    <origin rpy="0 0 0" xyz="-0.015 0.0 -0.152" />
    <parent link="steering_leftrear_link_1" />
    <child link="wheel_leftrear_link_1" />
    <axis xyz="-1.0 -0.0 -0.0" />
  </joint>

  <joint name="wheel_rightrear_joint" type="continuous">
    <origin rpy="0 0 3.14" xyz="0.015 0.0 -0.152" />
    <parent link="steering_rightrear_link_1" />
    <child link="wheel_rightrear_link_1" />
    <axis xyz="1.0 0.0 -0.0" />
  </joint>

  <joint name="wheel_rightfront_joint" type="continuous">
    <origin rpy="0 0 3.14" xyz="0.015 0.0 -0.152" />
    <parent link="steering_rightfront_link_1" />
    <child link="wheel_rightfront_link_1" />
    <axis xyz="1.0 0.0 -0.0" />
  </joint>

<!-- Zed head for plugin and joints-->
  <joint name="zed2_tilt_head_joint" type="fixed">
    <origin xyz="0.40 0.3 0.09" rpy="0 0.0 1.57"/>
    <parent link="base_link"/>
    <child link="zed2_tilt_head_link"/>
  </joint>

  <link name="zed2_tilt_head_link">
    <inertial>
      <mass value="0.108614"/>
      <origin xyz="0 -0.008564 0.015313"/>
      <inertia
        ixx="7.371e-5" ixy="0.0" ixz="1.326071e-6"
        iyy="3.14e-5" iyz="-1.424e-5"
        izz="6.13e-5"/>
    </inertial>
    <visual>
      <origin xyz="0 0 0" rpy="0 0 ${pi}"/>
      <geometry>
        <mesh filename="package://rover_22_description_zed/meshes/Manfrotto_head.dae"/>
      </geometry>
    </visual>
    <collision>
      <origin xyz="0 0 0" rpy="0 0 ${pi}"/>
      <geometry>
        <mesh filename="package://rover_22_description_zed/meshes/Manfrotto_head.dae"/>
      </geometry>
    </collision>
  </link>

  <joint name="zed2_camera_center_joint" type="fixed">
    <parent link="zed2_tilt_head_link"/>
    <child link="zed2_camera_center"/>
    <origin xyz="0 0 0.0486" rpy="0 0.0 0"/>
  </joint>

  <zed2 link_prefix="zed2_tilt_head_link" 
              joint_prefix="zed2_camera_center_joint"/>

  <!-- Activate zed plugin-->
  <xacro:zed2_gazebo robot_ns="robot_description"/>

  <!-- IMU plugin-->
  <gazebo>
    <plugin name="imu_controller" filename="libhector_gazebo_ros_imu.so">
      <updateRate>30.0</updateRate>
      <bodyName>base_link</bodyName>
      <topicName>/imu/data</topicName>
      <accelDrift>0.005 0.005 0.005</accelDrift>
      <accelGaussianNoise>0.005 0.005 0.005</accelGaussianNoise>
      <rateDrift>0.005 0.005 0.005 </rateDrift>
      <rateGaussianNoise>0.005 0.005 0.005 </rateGaussianNoise>
      <headingDrift>0.005</headingDrift>
      [ERROR] [1555346159.311804930, 0.098000000]:
      <headingGaussianNoise>0.005</headingGaussianNoise>
    </plugin>
  </gazebo>

  <!-- GPS plugin-->
  <gazebo>
    <plugin name="gps_controller" filename="libhector_gazebo_ros_gps.so">
      <updateRate>30</updateRate>
      <bodyName>base_link</bodyName>
      <frameId>base_link</frameId>
      <topicName>gps/fix</topicName>
      <velocityTopicName>navsat/vel</velocityTopicName>
      <referenceLatitude>41.1052670854</referenceLatitude>
      <referenceLongitude>29.023378124</referenceLongitude>
      <referenceHeading>0</referenceHeading>
      <referenceAltitude>0</referenceAltitude>
      <drift>0.0001 0.0001 0.0001</drift>
    </plugin>
  </gazebo>
</robot>